<?xml version="1.0"?>
<robot name="mini_pupper">
  <link name="base_link">
    <visual>
      <geometry><box size="0.209 0.108 0.045"/></geometry>
      <material name="yellow"><color rgba="1 0.8 0 1"/></material>
    </visual>
    <collision>
      <geometry><box size="0.209 0.108 0.045"/></geometry>
    </collision>
    <inertial>
      <mass value="0.506"/>
      <inertia ixx="0.0006" ixy="0.0" ixz="0.0" iyy="0.0015" iyz="0.0" izz="0.002"/>
    </inertial>
  </link>

  <joint name="fl_hip_joint" type="revolute">
    <parent link="base_link"/><child link="fl_hip"/>
    <origin xyz="0.09 0.05 0"/>
    <axis xyz="1 0 0"/>
    <limit lower="-0.8" upper="0.8" effort="3.0" velocity="6.0"/>
  </joint>
  <link name="fl_hip">
    <inertial>
      <mass value="0.06"/>
      <inertia ixx="0.00001" ixy="0.0" ixz="0.0" iyy="0.00001" iyz="0.0" izz="0.00001"/>
    </inertial>
  </link>

  <joint name="fl_thigh_joint" type="revolute">
    <parent link="fl_hip"/><child link="fl_thigh"/>
    <origin xyz="0 0.02 0"/>
    <axis xyz="0 1 0"/>
    <limit lower="-1.5" upper="4.5" effort="3.0" velocity="6.0"/>
  </joint>
  <link name="fl_thigh">
    <inertial>
      <mass value="0.04"/>
      <inertia ixx="0.00001" ixy="0.0" ixz="0.0" iyy="0.00001" iyz="0.0" izz="0.00001"/>
    </inertial>
  </link>

  <joint name="fl_calf_joint" type="revolute">
    <parent link="fl_thigh"/><child link="fl_calf"/>
    <origin xyz="0 0 -0.1"/>
    <axis xyz="0 1 0"/>
    <limit lower="-2.5" upper="-0.5" effort="3.0" velocity="6.0"/>
  </joint>
  <link name="fl_calf">
    <inertial>
      <mass value="0.02"/>
      <inertia ixx="0.00001" ixy="0.0" ixz="0.0" iyy="0.00001" iyz="0.0" izz="0.00001"/>
    </inertial>
  </link>

  <joint name="fr_hip_joint" type="revolute">
    <parent link="base_link"/><child link="fr_hip"/>
    <origin xyz="0.09 -0.05 0"/>
    <axis xyz="1 0 0"/>
    <limit lower="-0.8" upper="0.8" effort="3.0" velocity="6.0"/>
  </joint>
  <link name="fr_hip">
    <inertial>
      <mass value="0.06"/>
      <inertia ixx="0.00001" ixy="0.0" ixz="0.0" iyy="0.00001" iyz="0.0" izz="0.00001"/>
    </inertial>
  </link>

  <joint name="fr_thigh_joint" type="revolute">
    <parent link="fr_hip"/><child link="fr_thigh"/>
    <origin xyz="0 -0.02 0"/>
    <axis xyz="0 1 0"/>
    <limit lower="-1.5" upper="4.5" effort="3.0" velocity="6.0"/>
  </joint>
  <link name="fr_thigh">
    <inertial>
      <mass value="0.04"/>
      <inertia ixx="0.00001" ixy="0.0" ixz="0.0" iyy="0.00001" iyz="0.0" izz="0.00001"/>
    </inertial>
  </link>

  <joint name="fr_calf_joint" type="revolute">
    <parent link="fr_thigh"/><child link="fr_calf"/>
    <origin xyz="0 0 -0.1"/>
    <axis xyz="0 1 0"/>
    <limit lower="-2.5" upper="-0.5" effort="3.0" velocity="6.0"/>
  </joint>
  <link name="fr_calf">
    <inertial>
      <mass value="0.02"/>
      <inertia ixx="0.00001" ixy="0.0" ixz="0.0" iyy="0.00001" iyz="0.0" izz="0.00001"/>
    </inertial>
  </link>

  <joint name="bl_hip_joint" type="revolute">
    <parent link="base_link"/><child link="bl_hip"/>
    <origin xyz="-0.09 0.05 0"/>
    <axis xyz="1 0 0"/>
    <limit lower="-0.8" upper="0.8" effort="3.0" velocity="6.0"/>
  </joint>
  <link name="bl_hip">
    <inertial>
      <mass value="0.06"/>
      <inertia ixx="0.00001" ixy="0.0" ixz="0.0" iyy="0.00001" iyz="0.0" izz="0.00001"/>
    </inertial>
  </link>

  <joint name="bl_thigh_joint" type="revolute">
    <parent link="bl_hip"/><child link="bl_thigh"/>
    <origin xyz="0 0.02 0"/>
    <axis xyz="0 1 0"/>
    <limit lower="-1.5" upper="4.5" effort="3.0" velocity="6.0"/>
  </joint>
  <link name="bl_thigh">
    <inertial>
      <mass value="0.04"/>
      <inertia ixx="0.00001" ixy="0.0" ixz="0.0" iyy="0.00001" iyz="0.0" izz="0.00001"/>
    </inertial>
  </link>

  <joint name="bl_calf_joint" type="revolute">
    <parent link="bl_thigh"/><child link="bl_calf"/>
    <origin xyz="0 0 -0.1"/>
    <axis xyz="0 1 0"/>
    <limit lower="-2.5" upper="-0.5" effort="3.0" velocity="6.0"/>
  </joint>
  <link name="bl_calf">
    <inertial>
      <mass value="0.02"/>
      <inertia ixx="0.00001" ixy="0.0" ixz="0.0" iyy="0.00001" iyz="0.0" izz="0.00001"/>
    </inertial>
  </link>

  <joint name="br_hip_joint" type="revolute">
    <parent link="base_link"/><child link="br_hip"/>
    <origin xyz="-0.09 -0.05 0"/>
    <axis xyz="1 0 0"/>
    <limit lower="-0.8" upper="0.8" effort="3.0" velocity="6.0"/>
  </joint>
  <link name="br_hip">
    <inertial>
      <mass value="0.06"/>
      <inertia ixx="0.00001" ixy="0.0" ixz="0.0" iyy="0.00001" iyz="0.0" izz="0.00001"/>
    </inertial>
  </link>

  <joint name="br_thigh_joint" type="revolute">
    <parent link="br_hip"/><child link="br_thigh"/>
    <origin xyz="0 -0.02 0"/>
    <axis xyz="0 1 0"/>
    <limit lower="-1.5" upper="4.5" effort="3.0" velocity="6.0"/>
  </joint>
  <link name="br_thigh">
    <inertial>
      <mass value="0.04"/>
      <inertia ixx="0.00001" ixy="0.0" ixz="0.0" iyy="0.00001" iyz="0.0" izz="0.00001"/>
    </inertial>
  </link>

  <joint name="br_calf_joint" type="revolute">
    <parent link="br_thigh"/><child link="br_calf"/>
    <origin xyz="0 0 -0.1"/>
    <axis xyz="0 1 0"/>
    <limit lower="-2.5" upper="-0.5" effort="3.0" velocity="6.0"/>
  </joint>
  <link name="br_calf">
    <inertial>
      <mass value="0.02"/>
      <inertia ixx="0.00001" ixy="0.0" ixz="0.0" iyy="0.00001" iyz="0.0" izz="0.00001"/>
    </inertial>
  </link>
</robot>